<?xml version="1.0" encoding="utf-8"?>
<!-- This URDF was automatically created by SolidWorks to URDF Exporter! Originally created by Stephen Brawner (brawner@gmail.com) 
     Commit Version: 1.6.0-4-g7f85cfe  Build Version: 1.6.7995.38578
     For more information, please see http://wiki.ros.org/sw_urdf_exporter -->
<robot
  name="Endowrist Mockup.SLDASM">

  <!-- TEMPORARY -->
  <link name="base_link"></link>
  <joint name="base_link_to_base" type="fixed">
      <parent link="base_link" />
      <child link="endowrist_box" />
      <origin rpy="0.0 0 0" xyz="0 0 0" />
  </joint>
  <!-- TEMPORARY -->


  <link
    name="endowrist_box">
    <inertial>
      <origin
        xyz="-1.8273E-08 0.015299 -0.0033896"
        rpy="0 0 0" />
      <mass
        value="0.001699" />
      <inertia
        ixx="0.0001267"
        ixy="1.7466E-11"
        ixz="-3.1865E-11"
        iyy="0.00016301"
        iyz="-6.977E-07"
        izz="6.3272E-05" />
    </inertial>
    <visual>
      <origin
        xyz="0 0 0"
        rpy="0 0 0" />
      <geometry>
        <mesh
          filename="package://Endowrist Mockup.SLDASM/meshes/endowrist_box.obj" />
      </geometry>
      <material
        name="">
        <color
          rgba="0.79216 0.81961 0.93333 1" />
      </material>
    </visual>
    <collision>
      <origin
        xyz="0 0 0.011"
        rpy="0 0 0" />
      <geometry>
        <box size="0.065 0.095 0.022"/>
      </geometry>
    </collision>
  </link>
  <link
    name="endowrist_tube">
    <inertial>
      <origin
        xyz="9.4436E-09 -0.21543 4.421E-08"
        rpy="0 0 0" />
      <mass
        value="0.0010496" />
      <inertia
        ixx="0.00016247"
        ixy="1.789E-11"
        ixz="-3.4116E-13"
        iyy="1.4533E-07"
        iyz="8.1981E-11"
        izz="0.00016247" />
    </inertial>
    <visual>
      <origin
        xyz="0 0 0"
        rpy="0 0 0" />
      <geometry>
        <mesh
          filename="package://Endowrist Mockup.SLDASM/meshes/endowrist_tube.obj" />
      </geometry>
      <material
        name="">
        <color
          rgba="0.29804 0.29804 0.29804 1" />
      </material>
    </visual>
    <!-- <collision>
      <origin
        xyz="0 0 0"
        rpy="0 0 0" />
      <geometry>
        <mesh
          filename="package://Endowrist Mockup.SLDASM/meshes/endowrist_tube.obj" />
      </geometry>
    </collision> -->
  </link>
  <joint
    name="joint_endowrist_box_endowrist_tube"
    type="revolute">
    <origin
      xyz="0 -0.04764 0.0175"
      rpy="0 0 0" />
    <parent
      link="endowrist_box" />
    <child
      link="endowrist_tube" />
    <axis
      xyz="0 1 0" />
    <limit
      lower="-3.92699"
      upper="3.92699"
      effort="300"
      velocity="10" />
  </joint>
  <link

    name="endowrist_body">
    <inertial>
      <origin
        xyz="0.005352 -2.5216E-07 -6.2233E-15"
        rpy="0 0 0" />
      <mass
        value="0.00047278" />
      <inertia
        ixx="4.5231E-09"
        ixy="-1.4703E-23"
        ixz="9.3274E-25"
        iyy="9.8411E-09"
        iyz="3.0203E-17"
        izz="8.4079E-09" />
    </inertial>
    <visual>
      <origin
        xyz="0 0 0"
        rpy="0 0 0" />
      <geometry>
        <mesh
          filename="package://Endowrist Mockup.SLDASM/meshes/endowrist_body.obj" />
      </geometry>
      <material
        name="">
        <color
          rgba="0.79216 0.81961 0.93333 1" />
      </material>
    </visual>
    <!-- <collision>
      <origin
        xyz="0 0 0"
        rpy="0 0 0" />
      <geometry>
        <mesh
          filename="package://Endowrist Mockup.SLDASM/meshes/endowrist_body.obj" />
      </geometry>
    </collision> -->
  </link>
  <joint
    name="joint_endowrist_tube_endowrist_body"
    type="revolute">
    <origin
      xyz="0 -0.432 0"
      rpy="-1.5708 0 -1.5708" />
    <parent
      link="endowrist_tube" />
    <child
      link="endowrist_body" />
    <axis
      xyz="0 1 0" />
    <limit
      lower="-1.183"
      upper="1.183"
      effort="300"
      velocity="10" />
  </joint>
  <link

    name="endowrist_forcep1">
    <inertial>
      <origin
        xyz="0.0015257 0.0007449 -0.00019009"
        rpy="0 0 0" />
      <mass
        value="9.8579E-05" />
      <inertia
        ixx="3.1275E-10"
        ixy="1.1473E-10"
        ixz="7.2329E-11"
        iyy="1.3423E-09"
        iyz="-1.3939E-11"
        izz="1.1524E-09" />
    </inertial>
    <visual>
      <origin
        xyz="0 0 0"
        rpy="0 0 0" />
      <geometry>
        <mesh
          filename="package://Endowrist Mockup.SLDASM/meshes/endowrist_forcep1.obj" />
      </geometry>
      <material
        name="">
        <color
          rgba="0.79216 0.81961 0.93333 1" />
      </material>
    </visual>
    <!-- <collision>
      <origin
        xyz="0 0 0"
        rpy="0 0 0" />
      <geometry>
        <mesh
          filename="package://Endowrist Mockup.SLDASM/meshes/endowrist_forcep1.obj" />
      </geometry>
    </collision> -->
  </link>
  <joint
    name="joint_endowrist_body_endowrist_forcep1"
    type="revolute">
    <origin
      xyz="0.01 0 0"
      rpy="-1.5708 0 0" />
    <parent
      link="endowrist_body" />
    <child
      link="endowrist_forcep1" />
    <axis
      xyz="0 1 0" />
    <limit
      lower="-2.06140838"
      upper="2.06140838"
      effort="300"
      velocity="10" />
  </joint>
  <link
    name="endowrist_forcep2">
    <inertial>
      <origin
        xyz="0.0015623 -0.0007449 0.00018984"
        rpy="0 0 0" />
      <mass
        value="9.8579E-05" />
      <inertia
        ixx="3.1275E-10"
        ixy="-1.1473E-10"
        ixz="-7.2329E-11"
        iyy="1.3423E-09"
        iyz="-1.3939E-11"
        izz="1.1524E-09" />
    </inertial>
    <visual>
      <origin
        xyz="0 0 0"
        rpy="0 0 0" />
      <geometry>
        <mesh
          filename="package://Endowrist Mockup.SLDASM/meshes/endowrist_forcep2.obj" />
      </geometry>
      <material
        name="">
        <color
          rgba="0.79216 0.81961 0.93333 1" />
      </material>
    </visual>
    <!-- <collision>
      <origin
        xyz="0 0 0"
        rpy="0 0 0" />
      <geometry>
        <mesh
          filename="package://Endowrist Mockup.SLDASM/meshes/endowrist_forcep2.obj" />
      </geometry>
    </collision> -->
  </link>
  <joint
    name="joint_endowrist_body_endowrist_forcep2"
    type="revolute">
    <origin
      xyz="0.0099633 0 0"
      rpy="-1.5708 0 0" />
    <parent
      link="endowrist_body" />
    <child
      link="endowrist_forcep2" />
    <axis
      xyz="0 1 0" />
    <limit
      lower="-2.06140838"
      upper="2.06140838"
      effort="300"
      velocity="10" />
  </joint>


  <transmission name="tran_endowrist_box_endowrist_tube">
    <robotNamespace>/Endowrist Mockup.SLDASM</robotNamespace>
    <type>transmission_interface/SimpleTransmission</type>
    <joint name="joint_endowrist_box_endowrist_tube">
        <hardwareInterface>PositionJointInterface</hardwareInterface>
    </joint>
    <actuator name="motor_endowrist_box_endowrist_tube">
        <hardwareInterface>PositionJointInterface</hardwareInterface>
        <mechanicalReduction>1</mechanicalReduction>
        <drake:gear_ratio value="160.0" />
        <drake:rotor_inertia value="0.0001321" />
    </actuator>
  </transmission>
  <transmission name="tran_endowrist_tube_endowrist_body">
    <robotNamespace>/Endowrist Mockup.SLDASM</robotNamespace>
    <type>transmission_interface/SimpleTransmission</type>
    <joint name="joint_endowrist_tube_endowrist_body">
        <hardwareInterface>PositionJointInterface</hardwareInterface>
    </joint>
    <actuator name="motor_endowrist_tube_endowrist_body">
        <hardwareInterface>PositionJointInterface</hardwareInterface>
        <mechanicalReduction>1</mechanicalReduction>
        <drake:gear_ratio value="160.0" />
        <drake:rotor_inertia value="0.0001321" />
    </actuator>
  </transmission>
  <transmission name="tran_endowrist_body_endowrist_forcep1">
    <robotNamespace>/Endowrist Mockup.SLDASM</robotNamespace>
    <type>transmission_interface/SimpleTransmission</type>
    <joint name="joint_endowrist_body_endowrist_forcep1">
        <hardwareInterface>PositionJointInterface</hardwareInterface>
    </joint>
    <actuator name="motor_endowrist_body_endowrist_forcep1">
        <hardwareInterface>PositionJointInterface</hardwareInterface>
        <mechanicalReduction>1</mechanicalReduction>
        <drake:gear_ratio value="160.0" />
        <drake:rotor_inertia value="0.0001321" />
    </actuator>
  </transmission>
  <transmission name="tran_endowrist_body_endowrist_forcep2">
    <robotNamespace>/Endowrist Mockup.SLDASM</robotNamespace>
    <type>transmission_interface/SimpleTransmission</type>
    <joint name="joint_endowrist_body_endowrist_forcep2">
        <hardwareInterface>PositionJointInterface</hardwareInterface>
    </joint>
    <actuator name="motor_endowrist_body_endowrist_forcep2">
        <hardwareInterface>PositionJointInterface</hardwareInterface>
        <mechanicalReduction>1</mechanicalReduction>
        <drake:gear_ratio value="160.0" />
        <drake:rotor_inertia value="0.0001321" />
    </actuator>
  </transmission>
</robot>